2020-02-16 18:07:02,777 [ERROR]  Exception occurred while handling uri: 'http://localhost:5005/models/parse'
Traceback (most recent call last):
  File "c:\users\abhishek\anaconda3\lib\site-packages\sanic\app.py", line 893, in handle_request
    handler, args, kwargs, uri = self.router.get(request)
  File "c:\users\abhishek\anaconda3\lib\site-packages\sanic\router.py", line 407, in get
    return self._get(request.path, request.method, "")
  File "c:\users\abhishek\anaconda3\lib\site-packages\sanic\router.py", line 469, in _get
    raise NotFound("Requested URL {} not found".format(url))
sanic.exceptions.NotFound: Requested URL /models/parse not found
2020-02-16 18:09:08,981 [ERROR]  Experienced exception while trying to serve
Traceback (most recent call last):
  File "c:\users\abhishek\anaconda3\lib\site-packages\sanic\app.py", line 1096, in run
    serve(**server_settings)
  File "c:\users\abhishek\anaconda3\lib\site-packages\sanic\server.py", line 770, in serve
    loop.run_forever()
  File "c:\users\abhishek\anaconda3\lib\asyncio\base_events.py", line 528, in run_forever
    self._run_once()
  File "c:\users\abhishek\anaconda3\lib\asyncio\base_events.py", line 1728, in _run_once
    event_list = self._selector.select(timeout)
  File "c:\users\abhishek\anaconda3\lib\selectors.py", line 323, in select
    r, w, _ = self._select(self._readers, self._writers, [], timeout)
  File "c:\users\abhishek\anaconda3\lib\selectors.py", line 314, in _select
    r, w, x = select.select(r, w, w, timeout)
  File "c:\users\abhishek\anaconda3\lib\site-packages\socketio\client.py", line 25, in signal_handler
    return original_signal_handler(sig, frame)
  File "c:\users\abhishek\anaconda3\lib\site-packages\engineio\client.py", line 43, in signal_handler
    return original_signal_handler(sig, frame)
KeyboardInterrupt
2020-02-16 18:10:18,574 [ERROR]  Exception occurred while handling uri: 'http://localhost:5005/models/parse'
Traceback (most recent call last):
  File "c:\users\abhishek\anaconda3\lib\site-packages\sanic\app.py", line 893, in handle_request
    handler, args, kwargs, uri = self.router.get(request)
  File "c:\users\abhishek\anaconda3\lib\site-packages\sanic\router.py", line 407, in get
    return self._get(request.path, request.method, "")
  File "c:\users\abhishek\anaconda3\lib\site-packages\sanic\router.py", line 469, in _get
    raise NotFound("Requested URL {} not found".format(url))
sanic.exceptions.NotFound: Requested URL /models/parse not found
2020-02-16 18:14:37,101 [DEBUG]  Available web server routes: 
/conversations/<conversation_id>/messages          POST                           add_message
/conversations/<conversation_id>/tracker/events    POST                           append_event
/webhooks/rest                                     GET                            custom_webhook_RestInput.health
/webhooks/rest/webhook                             POST                           custom_webhook_RestInput.receive
/model/test/intents                                POST                           evaluate_intents
/model/test/stories                                POST                           evaluate_stories
/conversations/<conversation_id>/execute           POST                           execute_action
/domain                                            GET                            get_domain
/                                                  GET                            hello
/model                                             PUT                            load_model
/model/parse                                       POST                           parse
/conversations/<conversation_id>/predict           POST                           predict
/conversations/<conversation_id>/tracker/events    PUT                            replace_events
/conversations/<conversation_id>/story             GET                            retrieve_story
/conversations/<conversation_id>/tracker           GET                            retrieve_tracker
/status                                            GET                            status
/model/predict                                     POST                           tracker_predict
/model/train                                       POST                           train
/model                                             DELETE                         unload_model
/version                                           GET                            version
2020-02-16 18:16:07,058 [DEBUG]  Available web server routes: 
/conversations/<conversation_id>/messages          POST                           add_message
/conversations/<conversation_id>/tracker/events    POST                           append_event
/webhooks/rest                                     GET                            custom_webhook_RestInput.health
/webhooks/rest/webhook                             POST                           custom_webhook_RestInput.receive
/model/test/intents                                POST                           evaluate_intents
/model/test/stories                                POST                           evaluate_stories
/conversations/<conversation_id>/execute           POST                           execute_action
/domain                                            GET                            get_domain
/                                                  GET                            hello
/model                                             PUT                            load_model
/model/parse                                       POST                           parse
/conversations/<conversation_id>/predict           POST                           predict
/conversations/<conversation_id>/tracker/events    PUT                            replace_events
/conversations/<conversation_id>/story             GET                            retrieve_story
/conversations/<conversation_id>/tracker           GET                            retrieve_tracker
/status                                            GET                            status
/model/predict                                     POST                           tracker_predict
/model/train                                       POST                           train
/model                                             DELETE                         unload_model
/version                                           GET                            version
2020-02-16 18:26:18,830 [ERROR]  Exception occurred while handling uri: 'http://localhost:5005/favicon.ico'
Traceback (most recent call last):
  File "c:\users\abhishek\anaconda3\lib\site-packages\sanic\app.py", line 893, in handle_request
    handler, args, kwargs, uri = self.router.get(request)
  File "c:\users\abhishek\anaconda3\lib\site-packages\sanic\router.py", line 407, in get
    return self._get(request.path, request.method, "")
  File "c:\users\abhishek\anaconda3\lib\site-packages\sanic\router.py", line 469, in _get
    raise NotFound("Requested URL {} not found".format(url))
sanic.exceptions.NotFound: Requested URL /favicon.ico not found
2020-02-16 18:31:06,854 [ERROR]  Exception occurred while handling uri: 'http://localhost:5005/webhooks/rest/webhook'
Traceback (most recent call last):
  File "c:\users\abhishek\anaconda3\lib\site-packages\sanic\request.py", line 149, in load_json
    self.parsed_json = loads(self.body)
  File "c:\users\abhishek\anaconda3\lib\json\__init__.py", line 348, in loads
    return _default_decoder.decode(s)
  File "c:\users\abhishek\anaconda3\lib\json\decoder.py", line 337, in decode
    obj, end = self.raw_decode(s, idx=_w(s, 0).end())
  File "c:\users\abhishek\anaconda3\lib\json\decoder.py", line 353, in raw_decode
    obj, end = self.scan_once(s, idx)
json.decoder.JSONDecodeError: Expecting property name enclosed in double quotes: line 1 column 2 (char 1)

During handling of the above exception, another exception occurred:

Traceback (most recent call last):
  File "c:\users\abhishek\anaconda3\lib\site-packages\sanic\app.py", line 917, in handle_request
    response = await response
  File "c:\users\abhishek\anaconda3\lib\site-packages\rasa\core\channels\channel.py", line 430, in receive
    sender_id = await self._extract_sender(request)
  File "c:\users\abhishek\anaconda3\lib\site-packages\rasa\core\channels\channel.py", line 395, in _extract_sender
    return req.json.get("sender", None)
  File "c:\users\abhishek\anaconda3\lib\site-packages\sanic\request.py", line 143, in json
    self.load_json()
  File "c:\users\abhishek\anaconda3\lib\site-packages\sanic\request.py", line 153, in load_json
    raise InvalidUsage("Failed when parsing body as json")
sanic.exceptions.InvalidUsage: Failed when parsing body as json
2020-02-16 18:31:21,247 [ERROR]  Exception occurred while handling uri: 'http://localhost:5005/webhooks/rest/webhook'
Traceback (most recent call last):
  File "c:\users\abhishek\anaconda3\lib\site-packages\sanic\request.py", line 149, in load_json
    self.parsed_json = loads(self.body)
  File "c:\users\abhishek\anaconda3\lib\json\__init__.py", line 348, in loads
    return _default_decoder.decode(s)
  File "c:\users\abhishek\anaconda3\lib\json\decoder.py", line 337, in decode
    obj, end = self.raw_decode(s, idx=_w(s, 0).end())
  File "c:\users\abhishek\anaconda3\lib\json\decoder.py", line 353, in raw_decode
    obj, end = self.scan_once(s, idx)
json.decoder.JSONDecodeError: Expecting property name enclosed in double quotes: line 1 column 2 (char 1)

During handling of the above exception, another exception occurred:

Traceback (most recent call last):
  File "c:\users\abhishek\anaconda3\lib\site-packages\sanic\app.py", line 917, in handle_request
    response = await response
  File "c:\users\abhishek\anaconda3\lib\site-packages\rasa\core\channels\channel.py", line 430, in receive
    sender_id = await self._extract_sender(request)
  File "c:\users\abhishek\anaconda3\lib\site-packages\rasa\core\channels\channel.py", line 395, in _extract_sender
    return req.json.get("sender", None)
  File "c:\users\abhishek\anaconda3\lib\site-packages\sanic\request.py", line 143, in json
    self.load_json()
  File "c:\users\abhishek\anaconda3\lib\site-packages\sanic\request.py", line 153, in load_json
    raise InvalidUsage("Failed when parsing body as json")
sanic.exceptions.InvalidUsage: Failed when parsing body as json
2020-02-16 18:34:35,274 [ERROR]  Exception occurred while handling uri: 'http://localhost:5005/webhooks/rest/webhook'
Traceback (most recent call last):
  File "c:\users\abhishek\anaconda3\lib\site-packages\sanic\request.py", line 149, in load_json
    self.parsed_json = loads(self.body)
  File "c:\users\abhishek\anaconda3\lib\json\__init__.py", line 343, in loads
    s = s.decode(detect_encoding(s), 'surrogatepass')
UnicodeDecodeError: 'utf-8' codec can't decode byte 0x91 in position 0: invalid start byte

During handling of the above exception, another exception occurred:

Traceback (most recent call last):
  File "c:\users\abhishek\anaconda3\lib\site-packages\sanic\app.py", line 917, in handle_request
    response = await response
  File "c:\users\abhishek\anaconda3\lib\site-packages\rasa\core\channels\channel.py", line 430, in receive
    sender_id = await self._extract_sender(request)
  File "c:\users\abhishek\anaconda3\lib\site-packages\rasa\core\channels\channel.py", line 395, in _extract_sender
    return req.json.get("sender", None)
  File "c:\users\abhishek\anaconda3\lib\site-packages\sanic\request.py", line 143, in json
    self.load_json()
  File "c:\users\abhishek\anaconda3\lib\site-packages\sanic\request.py", line 153, in load_json
    raise InvalidUsage("Failed when parsing body as json")
sanic.exceptions.InvalidUsage: Failed when parsing body as json
2020-02-16 18:35:30,096 [ERROR]  Exception occurred while handling uri: 'http://localhost:5005/parse'
Traceback (most recent call last):
  File "c:\users\abhishek\anaconda3\lib\site-packages\sanic\app.py", line 893, in handle_request
    handler, args, kwargs, uri = self.router.get(request)
  File "c:\users\abhishek\anaconda3\lib\site-packages\sanic\router.py", line 407, in get
    return self._get(request.path, request.method, "")
  File "c:\users\abhishek\anaconda3\lib\site-packages\sanic\router.py", line 469, in _get
    raise NotFound("Requested URL {} not found".format(url))
sanic.exceptions.NotFound: Requested URL /parse not found
2020-02-16 18:36:11,358 [ERROR]  Exception occurred while handling uri: 'http://localhost:5005/parse'
Traceback (most recent call last):
  File "c:\users\abhishek\anaconda3\lib\site-packages\sanic\app.py", line 893, in handle_request
    handler, args, kwargs, uri = self.router.get(request)
  File "c:\users\abhishek\anaconda3\lib\site-packages\sanic\router.py", line 407, in get
    return self._get(request.path, request.method, "")
  File "c:\users\abhishek\anaconda3\lib\site-packages\sanic\router.py", line 469, in _get
    raise NotFound("Requested URL {} not found".format(url))
sanic.exceptions.NotFound: Requested URL /parse not found
